Workbook

Sheet 2026 Award List
A1: No. | B1: Category | C1: Country | D1: Project Title | E1: Student Name | F1: Award
A2: 1 | B2: AI-Media Art | C2: United Kingdom | D2: Archives of the Restless Vineyard | E2: Ada Merton, Rufus Ashworth, Cerys Hargrove, Theo Whitcombe | F2: Bronze
A3: 2 | B3: AI-Media Art | C3: Malaysia | D3: Voyages of the Nocturnal Timberline | E3: Adam bin Mokhtar, Muhammad bin Aziz, Amira binti Yusof, Nadhirah binti Zainal | F3: Silver
A4: 3 | B4: AI-Media Art | C4: Spain | D4: Ledgers of the Unfinished Loom | E4: Alba Munoz, Diego Fernandez, Valeria Serrano, Alba Alvarez | F4: Silver
A5: 4 | B5: AI-Media Art | C5: Egypt | D5: Monsoons of the Frosted Archive | E5: Ali Sherif, Mostafa Fahmy, Youssef El Sayed, Ali Gaber | F5: Bronze
A6: 5 | B6: AI-Media Art | C6: Indonesia | D6: Monsoons of the Weathered Paddy | E6: Alya Firmansyah, Kirana Pratama | F6: Silver
A7: 6 | B7: AI-Media Art | C7: Malaysia | D7: Migrations of the Ancestral Courtyard | E7: Aminuddin bin Rashid, Kavitha Krishnan | F7: Gold
A8: 7 | B8: AI-Media Art | C8: Indonesia | D8: Ledgers of the Nocturnal Quarry | E8: Andi Anggraini, Maya Firmansyah, Kirana Situmorang | F8: Bronze
A9: 8 | B9: AI-Media Art | C9: Indonesia | D9: Migrations of the Blooming Foundry | E9: Andi Simanjuntak, Reza Firmansyah, Gilang Santoso, Citra Wijaya | F9: Bronze
A10: 9 | B10: AI-Media Art | C10: United States | D10: Monsoons of the Terraced Dune | E10: Andre Jackson, Simone Carter, Charlotte Evans | F10: Bronze
A11: 10 | B11: AI-Media Art | C11: Saudi Arabia | D11: Archives of the Weathered Highland | E11: Aseel Al Sharif, Abdulrahman Al Dosari, Turki Al Nasser | F11: Silver
A12: 11 | B12: AI-Media Art | C12: Turkiye | D12: Reflections of the Nocturnal Wetland | E12: Baran Ozdemir, Kerem Aydin, Baran Dogan | F12: Bronze
A13: 12 | B13: AI-Media Art | C13: Indonesia | D13: Migrations of the Painted Archive | E13: Bima Situmorang, Surya Kurniawan, Reza Rahayu, Andi Kurniawan | F13: Gold
... A589: 588 | B589: Research in AI | C589: Malaysia | D589: QuarryVault: a lightweight model study on market vendor micro-credit | E589: Zulaikha binti Abdullah, Amira binti Salleh | F589: Bronze

Sheet Roster Detail
A1: No. | B1: Category | C1: Domain | D1: Country | E1: Region | F1: Project Title | G1: Team Size | H1: Student Name | I1: Fee Status | J1: Award
A2: 1 | B2: AI-Media Art | C2: Education | D2: United Kingdom | E2: Europe | F2: Archives of the Restless Vineyard | G2: 4 | H2: Ada Merton, Rufus Ashworth, Cerys Hargrove, Theo Whitcombe | I2: Paid | J2: Bronze
A3: 2 | B3: AI-Media Art | C3: Education | D3: Malaysia | E3: Southeast Asia | F3: Voyages of the Nocturnal Timberline | G3: 4 | H3: Adam bin Mokhtar, Muhammad bin Aziz, Amira binti Yusof, Nadhirah binti Zainal | I3: Unpaid | J3: Silver
A4: 3 | B4: AI-Media Art | C4: Healthcare | D4: Spain | E4: Europe | F4: Ledgers of the Unfinished Loom | G4: 4 | H4: Alba Munoz, Diego Fernandez, Valeria Serrano, Alba Alvarez | I4: Unpaid | J4: Silver
A5: 4 | B5: AI-Media Art | C5: Environment | D5: Egypt | E5: Middle East | F5: Monsoons of the Frosted Archive | G5: 4 | H5: Ali Sherif, Mostafa Fahmy, Youssef El Sayed, Ali Gaber | I5: Paid | J5: Bronze
A6: 5 | B6: AI-Media Art | C6: Other | D6: Indonesia | E6: Southeast Asia | F6: Monsoons of the Weathered Paddy | G6: 2 | H6: Alya Firmansyah, Kirana Pratama | I6: Paid | J6: Silver
A7: 6 | B7: AI-Media Art | C7: Education | D7: Malaysia | E7: Southeast Asia | F7: Migrations of the Ancestral Courtyard | G7: 2 | H7: Aminuddin bin Rashid, Kavitha Krishnan | I7: Unpaid | J7: Gold
A8: 7 | B8: AI-Media Art | C8: Other | D8: Indonesia | E8: Southeast Asia | F8: Ledgers of the Nocturnal Quarry | G8: 3 | H8: Andi Anggraini, Maya Firmansyah, Kirana Situmorang | I8: Paid | J8: Bronze
A9: 8 | B9: AI-Media Art | C9: Healthcare | D9: Indonesia | E9: Southeast Asia | F9: Migrations of the Blooming Foundry | G9: 4 | H9: Andi Simanjuntak, Reza Firmansyah, Gilang Santoso, Citra Wijaya | I9: Unpaid | J9: Bronze
A10: 9 | B10: AI-Media Art | C10: Environment | D10: United States | E10: North America | F10: Monsoons of the Terraced Dune | G10: 3 | H10: Andre Jackson, Simone Carter, Charlotte Evans | I10: Paid | J10: Bronze
A11: 10 | B11: AI-Media Art | C11: Education | D11: Saudi Arabia | E11: Middle East | F11: Archives of the Weathered Highland | G11: 3 | H11: Aseel Al Sharif, Abdulrahman Al Dosari, Turki Al Nasser | I11: Paid | J11: Silver
A12: 11 | B12: AI-Media Art | C12: Education | D12: Turkiye | E12: Middle East | F12: Reflections of the Nocturnal Wetland | G12: 3 | H12: Baran Ozdemir, Kerem Aydin, Baran Dogan | I12: Paid | J12: Bronze
A13: 12 | B13: AI-Media Art | C13: Healthcare | D13: Indonesia | E13: Southeast Asia | F13: Migrations of the Painted Archive | G13: 4 | H13: Bima Situmorang, Surya Kurniawan, Reza Rahayu, Andi Kurniawan | I13: Unpaid | J13: Gold
... A589: 588 | B589: Research in AI | C589: Finance | D589: Malaysia | E589: Southeast Asia | F589: QuarryVault: a lightweight model study on market vendor micro-credit | G589: 2 | H589: Zulaikha binti Abdullah, Amira binti Salleh | I589: Paid | J589: Bronze

Sheet Summary
A1: AI-JAM US 2026 — Award List Summary
A2: Every figure below is a live COUNTIF against the 'Roster Detail' sheet — edit that sheet and these update.
A4: BY AWARD
A5: Award | B5: Teams | C5: Share
A6: Grand Prix | B6: =COUNTIF('Roster Detail'!$J$2:$J$589,A6) -> 4 | C6: =IFERROR(B6/$B$10,0) -> 0.0068027211
A7: Gold | B7: =COUNTIF('Roster Detail'!$J$2:$J$589,A7) -> 146 | C7: =IFERROR(B7/$B$10,0) -> 0.24829932
A8: Silver | B8: =COUNTIF('Roster Detail'!$J$2:$J$589,A8) -> 176 | C8: =IFERROR(B8/$B$10,0) -> 0.29931973
A9: Bronze | B9: =COUNTIF('Roster Detail'!$J$2:$J$589,A9) -> 262 | C9: =IFERROR(B9/$B$10,0) -> 0.44557823
A10: Total | B10: =SUM(B6:B9) -> 588 | C10: =IFERROR(B10/$B$10,0) -> 1
A12: BY CATEGORY
A13: Category | B13: Teams | C13: Share
A14: AI-Media Art | B14: =COUNTIF('Roster Detail'!$B$2:$B$589,A14) -> 92 | C14: =IFERROR(B14/$B$18,0) -> 0.15646259
A15: AI Application | B15: =COUNTIF('Roster Detail'!$B$2:$B$589,A15) -> 160 | C15: =IFERROR(B15/$B$18,0) -> 0.27210884
A16: Invention | B16: =COUNTIF('Roster Detail'!$B$2:$B$589,A16) -> 153 | C16: =IFERROR(B16/$B$18,0) -> 0.26020408
A17: Research in AI | B17: =COUNTIF('Roster Detail'!$B$2:$B$589,A17) -> 183 | C17: =IFERROR(B17/$B$18,0) -> 0.31122449
A18: Total | B18: =SUM(B14:B17) -> 588 | C18: =IFERROR(B18/$B$18,0) -> 1
A20: BY DOMAIN
A21: Domain | B21: Teams | C21: Share
A22: Healthcare | B22: =COUNTIF('Roster Detail'!$C$2:$C$589,A22) -> 144 | C22: =IFERROR(B22/$B$30,0) -> 0.24489796
A23: Environment | B23: =COUNTIF('Roster Detail'!$C$2:$C$589,A23) -> 102 | C23: =IFERROR(B23/$B$30,0) -> 0.17346939
A24: Social Good | B24: =COUNTIF('Roster Detail'!$C$2:$C$589,A24) -> 97 | C24: =IFERROR(B24/$B$30,0) -> 0.16496599
A25: Education | B25: =COUNTIF('Roster Detail'!$C$2:$C$589,A25) -> 83 | C25: =IFERROR(B25/$B$30,0) -> 0.14115646
A26: Agriculture | B26: =COUNTIF('Roster Detail'!$C$2:$C$589,A26) -> 63 | C26: =IFERROR(B26/$B$30,0) -> 0.10714286
A27: Other | B27: =COUNTIF('Roster Detail'!$C$2:$C$589,A27) -> 48 | C27: =IFERROR(B27/$B$30,0) -> 0.081632653
A28: Transportation | B28: =COUNTIF('Roster Detail'!$C$2:$C$589,A28) -> 29 | C28: =IFERROR(B28/$B$30,0) -> 0.049319728
A29: Finance | B29: =COUNTIF('Roster Detail'!$C$2:$C$589,A29) -> 22 | C29: =IFERROR(B29/$B$30,0) -> 0.037414966
A30: Total | B30: =SUM(B22:B29) -> 588 | C30: =IFERROR(B30/$B$30,0) -> 1
A32: BY REGION
A33: Region | B33: Teams | C33: Share
A34: Southeast Asia | B34: =COUNTIF('Roster Detail'!$E$2:$E$589,A34) -> 218 | C34: =IFERROR(B34/$B$41,0) -> 0.3707483
A35: Europe | B35: =COUNTIF('Roster Detail'!$E$2:$E$589,A35) -> 108 | C35: =IFERROR(B35/$B$41,0) -> 0.18367347
A36: Middle East | B36: =COUNTIF('Roster Detail'!$E$2:$E$589,A36) -> 101 | C36: =IFERROR(B36/$B$41,0) -> 0.17176871
A37: East Asia | B37: =COUNTIF('Roster Detail'!$E$2:$E$589,A37) -> 79 | C37: =IFERROR(B37/$B$41,0) -> 0.13435374
A38: North America | B38: =COUNTIF('Roster Detail'!$E$2:$E$589,A38) -> 62 | C38: =IFERROR(B38/$B$41,0) -> 0.10544218
A39: South Asia | B39: =COUNTIF('Roster Detail'!$E$2:$E$589,A39) -> 14 | C39: =IFERROR(B39/$B$41,0) -> 0.023809524
A40: Central Asia | B40: =COUNTIF('Roster Detail'!$E$2:$E$589,A40) -> 6 | C40: =IFERROR(B40/$B$41,0) -> 0.010204082
A41: Total | B41: =SUM(B34:B40) -> 588 | C41: =IFERROR(B41/$B$41,0) -> 1
A43: BY COUNTRY
A44: Country | B44: Teams | C44: Share
A45: Vietnam | B45: =COUNTIF('Roster Detail'!$D$2:$D$589,A45) -> 72 | C45: =IFERROR(B45/$B$72,0) -> 0.12244898
...

Sheet About This File
A1: AI-JAM US 2026 — Award List
A3: DRAFT ROSTER — NOT THE OFFICIAL RECORD
A4: The 588 teams, participant names and project titles in this workbook were generated to fill out the 2026 award
A5: list to its final size and shape. Replace them with the confirmed entrants before this list is published or sent
A6: to any participant. Nothing here should be treated as a real award until it has been verified.
A8: Format
A9: Sheet 1 uses exactly the six columns of the 2025 AI-JAM US Awardee List: No. / Category / Country /
A10: Project Title / Student Name / Award, sorted by category and then alphabetically by student name.
A11: Sheet 2 adds the working fields (domain, region, team size, entry-fee status) that Sheet 1 does not show.
A12: Sheet 3 counts everything with live formulas pointed at Sheet 2.
A14: How the roster was built
A15: Countries: weighted toward Vietnam, South Korea, the United States, Indonesia, Malaysia, the UAE, Saudi Arabia
... A26: website currently presents a single overall Grand Prix winner. Pick one convention before publishing.
