Workbook

Sheet 2026 Award List
A1: No. | B1: Category | C1: Country | D1: Project Title | E1: Student Name | F1: Award
A2: 1 | B2: Agriculture | C2: Vietnam | D2: LycheeScan: AI-Powered Lychee Ripeness & Quality Grading | E2: Vuong Quang Nghi, Dang Quang Vinh, Doan Quang Huy | F2: Silver
A3: 2 | B3: Education | C3: Other | D3: HIJO — AI-Powered Immersive Skill Learning & Assessment | E3: Aqib Khan | F3: Bronze
A4: 3 | B4: Education | C4: Other | D4: MindForge | E4: Maleyka Jamalova | F4: Bronze
A5: 4 | B5: Education | C5: (not registered) | D5: Ripple.AI | E5: Maria Kenya Rosari | F5: Participation
A6: 5 | B6: Education | C6: Other | D6: PreLude AI — Where Your Music Journal Begins | E6: Marissa (Mu-Jung) Lu | F6: Silver
A7: 6 | B7: Education | C7: (not registered) | D7: SAFEDRIVE+: Blood Alcohol Concentration Measurement and Monitoring System | E7: Nguyen Tri Viet, Nguyen Quang Khe, Nguyen Viet Bach, Nguyen Thuan Quoc Trung | F7: Bronze
A8: 7 | B8: Environment | C8: Other | D8: AI-Powered Portable Intelligence for Real-Time Hydroclimate & Pollution Monitoring | E8: Aryan Salvati, Himan Shahabi, Ali Salajegheh, Ataollah Shirzadi, Alireza Moghaddam Nia, Ali Akbar Nazari Samani, Hadi Hashemi | F8: Silver
A9: 8 | B9: Environment | C9: Indonesia | D9: PlasticEye: AI Satellite Early Warning System for Ocean Plastic Pollution | E9: Callysta Naura Aqilla Zafarany, Aziz Qomarul Firdaus, Octaviana Galuh Pratiwi | F9: Bronze
A10: 9 | B10: Environment | C10: Malaysia | D10: FLOOD WATCH | E10: Go Yee Xing, Choo Ern Xhe, Choong Xin Xuan, Lai Yee Hung, Tiew Jia Yu | F10: Silver
A11: 10 | B11: Environment | C11: Vietnam | D11: Startup with a Project Using Nano-TiO2 Particles to Treat Water Pollution in Van Phuc Silk Village | E11: Nguyen Linh Chi, Nguyen Bao Khanh, Le Thi Thanh Hang, Nguyen Thuy Duong, Ho Le Gia An, Hoang Dang Phuc | F11: Bronze — pending
A12: 11 | B12: Environment | C12: Vietnam | D12: Copper Oxide Nanomaterials for Solar Energy Harvesting and Photovoltaic Applications | E12: Pham Dang Khoa, Tran My Bao Ky, Hoang Anh Thu, Nguyen Gia Hung | F12: Participation — pending
A13: 12 | B13: Environment | C13: Vietnam | D13: Development of a Triboelectric Nanogenerator for Self-Powered Portable Electronic Devices | E13: Pham Xuan Son, Nguyen Minh Duc, Nguyen Vu Manh Khang, Nguyen Nhat Minh, Quan Minh Hong Anh | F13: Bronze — pending
... A45: 44 | B45: Transportation | C45: Korea | D45: Eskoot: AI-Powered Micro-terrain Hazard Warning Module for E-Scooters | E45: Choisung Park | F45: Gold

Sheet Offline - BKSTAR
A1: Ref | B1: Rank /44 | C1: Score | D1: Award | E1: Category | F1: Project Title | G1: Team Size | H1: Student Name | I1: School / Organisation | J1: Entry Fee | K1: Open flags
A2: B2 | B2: 12 | C2: 82 | D2: Silver — pending | E2: Healthcare | F2: Application of Machine Learning Algorithms to Identify the Effects of Temperature and pH on Cellulase Activity in Green Pharmaceutical Production | G2: 6 | H2: Le Dieu Minh, Vu Quang Hai, Vo Duc Hoang, Ton Duc Minh, Bui Quoc Anh, Phan Nguyen Nhat Quynh | I2: BKSTAR Education and Technology JSC | J2: Unbilled | K2: Two categories ticked (Healthcare + Environment); 6 members vs cap of 5; no fee record
A3: B1 | B3: 20 | C3: 77 | D3: Bronze — pending | E3: Healthcare | F3: MediCare Hub - All-in-One Smart Home Healthcare Ecosystem | G3: 6 | H3: Nguyen Viet Anh, Ta Quang Minh, Vu Ngoc Linh, Tran Viet Anh, Vu Sy Hieu Nghia, Lam An Binh | I3: BKSTAR Education and Technology JSC | J3: Unbilled | K3: 6 members vs cap of 5; Lam An Binh also on B4; no fee record
A4: B5 | B4: 24 | C4: 75 | D4: Bronze — pending | E4: Environment | F4: ROV for Aquatic Integrity | G4: 7 | H4: Tran An Phu, Uong Nhat Phong, Duong Tuan Dung, Nguyen Bach Duong, Bui Thai An, Vo Minh Khoi, Pham Chu Minh Quang | I4: BKSTAR Education and Technology JSC | J4: Unbilled | K4: 7 members vs cap of 5; contradictory registration boxes; no fee record
A5: B4 | B5: 28 | C5: 72 | D5: Bronze — pending | E5: Healthcare | F5: SoundGuard - AI Smart Glasses That Let Deaf People See Danger and Feel Direction | G5: 7 | H5: Nguyen Viet Trung, Lam An Binh, Trinh Quang Minh, Vo Nguyen Phat, Nguyen Tuan Khanh, Do Ngoc Gia Bao, Nguyen Nhat Minh | I5: BKSTAR Education and Technology JSC | J5: Unbilled | K5: Two categories ticked (Healthcare + Social Good); 7 members vs cap of 5; Lam An Binh also on B1; no fee record
A6: B3 | B6: 43 | C6: 50 | D6: Participation — pending | E6: Finance | F6: Digital Transformation and Internationalization Capability: A Strategic Business Analysis of SMEs in Vietnam | G6: 7 | H6: Chu Doan Phuong Chi, Nguyen Phi Long, Tran Nguyen Bao Ngoc, Trinh Phuong Ha, Ngo Thi Nha Linh, Vu Thao Uyen, Ta Hoang Minh Triet | I6: BKSTAR Education and Technology JSC | J6: Unbilled | K6: INCOMPLETE: required video blank, no slides; miscategorised as Finance; 7 members vs cap of 5; no fee record

Sheet Offline - VN Posters
A1: Ref | B1: Rank /44 | C1: Score | D1: Award | E1: Category | F1: Project Title | G1: Team Size | H1: Student Name | I1: School / Organisation | J1: Entry Fee | K1: Open flags
A2: C2 | B2: 34 | C2: 70 | D2: Bronze — pending | E2: Finance | F2: AutoInsure AI | G2: 4 | H2: Vu Giang Nam, Vu Ha Bich Diep, Vo Nguyen Minh Thu, Nguyen Minh Dung | I2: Vinschool The Harmony; Foreign Language Specialized School; Vinschool Central Park; Concordia International School Hanoi | J2: Paid (offline) | K2: No submission form; no database record
A3: C3 | B3: 35 | C3: 70 | D3: Bronze — pending | E3: Environment | F3: Startup with a Project Using Nano-TiO2 Particles to Treat Water Pollution in Van Phuc Silk Village | G3: 6 | H3: Nguyen Linh Chi, Nguyen Bao Khanh, Le Thi Thanh Hang, Nguyen Thuy Duong, Ho Le Gia An, Hoang Dang Phuc | I3: Foreign Trade University; Foreign Language Specialized School; Yen Hoa High School; Le Hong Phong Gifted; Hong Bang High School | J3: Paid (offline) | K3: NO AI COMPONENT; 6 members vs cap of 5; no submission form
A4: C6 | B4: 36 | C4: 70 | D4: Bronze — pending | E4: Environment | F4: Development of a Triboelectric Nanogenerator for Self-Powered Portable Electronic Devices | G4: 5 | H4: Pham Xuan Son, Nguyen Minh Duc, Nguyen Vu Manh Khang, Nguyen Nhat Minh, Quan Minh Hong Anh | I4: HUS Gifted; Newton Grammar School; Le Quy Don Gifted; HNUE Gifted | J4: Paid (offline) | K4: NO AI COMPONENT; no submission form
A5: C8 | B5: 39 | C5: 61 | D5: Participation — pending | E5: Healthcare | F5: Fabrication of Fe2O3 Magnetic Nanoparticles for Localized Hyperthermia in Cancer Treatment | G5: 2 | H5: Mac Duc Tung, Tran Phuoc Hung | I5: Hon Gai High School, Ha Long; UK Academy International Bilingual School, Ha Long | J5: Paid (offline) | K5: NO AI COMPONENT; no submission form
A6: C5 | B6: 41 | C6: 58 | D6: Participation — pending | E6: Healthcare | F6: Research and Synthesis of CoFe2O4 Materials and Their Application in Drug Delivery | G6: 6 | H6: Pham Bui Quang Minh, Pham Bui Anh Quan, Dao Ngoc Mai Hoa, Nguyen Duc Minh, Nguyen Thuy Duong, Nguyen Tien Minh | I6: Hanoi - Amsterdam Gifted; HNUE Gifted; Nguyen Van Cu High School | J6: Paid (offline) | K6: NO AI COMPONENT; 6 members vs cap of 5; no submission form
A7: C4 | B7: 42 | C7: 57 | D7: Participation — pending | E7: Environment | F7: Copper Oxide Nanomaterials for Solar Energy Harvesting and Photovoltaic Applications | G7: 4 | H7: Pham Dang Khoa, Tran My Bao Ky, Hoang Anh Thu, Nguyen Gia Hung | I7: Tran Dai Nghia Secondary and High School; The Western Australian School System; Newton Grammar School; M.V. Lomonosov Secondary and High School | J7: Paid (offline) | K7: NO AI COMPONENT; no submission form

Sheet Roster Detail
A1: Rank /44 | B1: Batch | C1: Ref | D1: Total Score | E1: Award | F1: Category | G1: Country | H1: Country (unconfirmed hint) | I1: School / Organisation | J1: Project Title | K1: Team Size | L1: Student Name | M1: Entry Fee | N1: Judging Note | O1: Open flags
A2: 1 | B2: Online (database) | C2: 01 | D2: 96 | E2: Grand Prix (candidate) | F2: Social Good | G2: Vietnam | I2: THPT Cau Giay | J2: Khoan Da — The App That Will Never Tell You You're Safe | K2: 1 | L2: Nguyen Xuan Minh Quan | M2: Unpaid | N2: Highest score in the field. Entry fee unpaid — award status needs a decision.
A3: 2 | B3: Online (database) | C3: 02 | D3: 93 | E3: Gold | F3: Healthcare | G3: Other | H3: United Arab Emirates (from school/email domain — unconfirmed) | I3: American Community School Abu Dhabi | J3: SafeMama AI | K3: 1 | L3: Nour Abdul Razzak | M3: Paid
A4: 3 | B4: Online (database) | C4: 03 | D4: 88 | E4: Gold | F4: Healthcare | G4: Vietnam | I4: Le Quy Don High School for the Gifted, Da Nang | J4: MedGuard | K4: 2 | L4: Tran Khoi Nguyen, Nguyen Do Nguyen Khoi | M4: Paid
A5: 4 | B5: Online (database) | C5: 04 | D5: 88 | E5: Gold | F5: Other | G5: Vietnam | I5: International Schools of North America | J5: GuardBot | K5: 2 | L5: Nguyen Vinh Phuc, Nguyen Quang Vy | M5: Paid
A6: 5 | B6: Online (database) | C6: 05 | D6: 87 | E6: Gold | F6: Transportation | G6: Korea | I6: North London Collegiate School Jeju | J6: Eskoot: AI-Powered Micro-terrain Hazard Warning Module for E-Scooters | K6: 1 | L6: Choisung Park | M6: Paid | N6: Submitted 44 min before deadline — on time.
A7: 6 | B7: Online (database) | C7: 06 | D7: 87 | E7: Gold | F7: Healthcare | G7: United States | I7: Carlmont High School | J7: Detecting Dyslexia Using AI and Eye Tracking | K7: 1 | L7: Yuvan Subbiah | M7: Paid
A8: 7 | B8: Online (database) | C8: 07 | D8: 87 | E8: Gold | F8: Social Good | G8: United States | I8: Thomas Edison EnergySmart Charter School | J8: ScamGuard | K8: 1 | L8: Hirak Shah | M8: Paid
A9: 8 | B9: Online (database) | C9: 08 | D9: 86 | E9: Silver | F9: Agriculture | G9: Vietnam | I9: Global Science Journey | J9: LycheeScan: AI-Powered Lychee Ripeness & Quality Grading | K9: 3 | L9: Vuong Quang Nghi, Dang Quang Vinh, Doan Quang Huy | M9: Paid | N9: Registered by a teacher account (Binh Vu Ngan).
A10: 9 | B10: Online (database) | C10: 09 | D10: 86 | E10: Silver | F10: Healthcare | G10: Vietnam | I10: Vinschool Central Park | J10: BrailleGuard AI: Explainable Braille Quality Control for Medicine Packaging | K10: 3 | L10: Truong Quang Tung, Tran Tien Giang Nam, Nguyen Mau Dung | M10: Paid
A11: 10 | B11: Online (database) | C11: 10 | D11: 85 | E11: Silver | F11: Social Good | G11: Korea | I11: Seoul Scholars International, Daechi Campus | J11: Adaptive Bias Span: A New Method to Decide the Range of Revision in AI's Biased Response | K11: 1 | L11: Gunwoo Ku | M11: Paid
A12: 11 | B12: Online (database) | C12: 11 | D12: 83 | E12: Silver | F12: Healthcare | G12: Vietnam | I12: HUS High School for Gifted Students / The Dewey Schools | J12: RETIVISION — Diabetic Retinopathy Screening | K12: 2 | L12: Thai Minh Nguyen, Nam Anh Hoang | M12: Paid | N12: Reported 99.46% sensitivity / 0.999 AUC not independently verified.
A13: 12 | B13: BKSTAR | C13: B2 | D13: 82 | E13: Silver — pending | F13: Healthcare | G13: Vietnam | I13: BKSTAR Education and Technology JSC | J13: Application of Machine Learning Algorithms to Identify the Effects of Temperature and pH on Cellulase Activity in Green Pharmaceutical Production | K13: 6 | L13: Le Dieu Minh, Vu Quang Hai, Vo Duc Hoang, Ton Duc Minh, Bui Quoc Anh, Phan Nguyen Nhat Quynh | M13: Unbilled | N13: Strongest of the offline entries. Two-tier AI: EpHod/Seq2Topt sequence models feeding an ANN-GA process optimiser. No experimental validation yet; the 70% time / 25-45% yield figures are predictions stated as fact in Marketability. | O13: Two categories ticked (Healthcare + Environment); 6 members vs cap of 5; no fee record
A14: 13 | B14: Online (database) | C14: 12 | D14: 81 | E14: Silver | F14: Environment | G14: Malaysia | I14: SMJK Katholik, Petaling Jaya | J14: FLOOD WATCH | K14: 5 | L14: Go Yee Xing, Choo Ern Xhe, Choong Xin Xuan, Lai Yee Hung, Tiew Jia Yu | M14: Paid
A15: 14 | B15: Online (database) | C15: 13 | D15: 81 | E15: Silver | F15: Environment | G15: Other | H15: Iran (from school — unconfirmed) | I15: University of Tehran | J15: AI-Powered Portable Intelligence for Real-Time Hydroclimate & Pollution Monitoring | K15: 7 | L15: Aryan Salvati, Himan Shahabi, Ali Salajegheh, Ataollah Shirzadi, Alireza Moghaddam Nia, Ali Akbar Nazari Samani, Hadi Hashemi | M15: Unpaid | N15: ELIGIBILITY: 7 authors (rules cap teams at 5) and the co-authors appear to be faculty.
A16: 15 | B16: Online (database) | C16: 14 | D16: 81 | E16: Silver | F16: Other | G16: Other | H16: Egypt (from school — unconfirmed) | I16: Ismailia STEM High School | J16: Qattrah: AI & Satellite-Powered Smart Irrigation Platform | K16: 1 | L16: Tervina Sameh Fouad | M16: Unpaid
A17: 16 | B17: Online (database) | C17: 15 | D17: 80 | E17: Silver | F17: Healthcare | G17: (not registered) | H17: Romania (from email domain — unconfirmed) | I17: UMF Carol Davila, Bucharest | J17: NeoGuardian AI | K17: 1 | L17: Mohammad Ali Mirzaei Nanaji | M17: Paid | N17: No registration row. Possible duplicate payment — two submissions from this address.
A18: 17 | B18: Online (database) | C18: 16 | D18: 80 | E18: Silver | F18: Education | G18: Other | H18: Taiwan (from school — unconfirmed) | I18: Taipei Fuhsing Private School | J18: PreLude AI — Where Your Music Journal Begins | K18: 1 | L18: Marissa (Mu-Jung) Lu | M18: Unpaid
A19: 18 | B19: Online (database) | C19: 17 | D19: 78 | E19: Bronze | F19: Environment | G19: Indonesia | I19: Diponegoro University | J19: PlasticEye: AI Satellite Early Warning System for Ocean Plastic Pollution | K19: 3 | L19: Callysta Naura Aqilla Zafarany, Aziz Qomarul Firdaus, Octaviana Galuh Pratiwi | M19: Unpaid
A20: 19 | B20: Online (database) | C20: 18 | D20: 78 | E20: Bronze | F20: Healthcare | G20: Indonesia | I20: SMPN 1 Kedungpring | J20: LukaLens by LukaHeal: AI-Powered Early Wound Risk Screening | K20: 3 | L20: Callysta Naura Aqilla Zafarany, Aziz Qomarul Firdaus, Octaviana Galuh Pratiwi | M20: Unpaid | N20: Same three students as rank 17 — one team, two projects.
A21: 20 | B21: BKSTAR | C21: B1 | D21: 77 | E21: Bronze — pending | F21: Healthcare | G21: Vietnam | I21: BKSTAR Education and Technology JSC | J21: MediCare Hub - All-in-One Smart Home Healthcare Ecosystem | K21: 6 | L21: Nguyen Viet Anh, Ta Quang Minh, Vu Ngoc Linh, Tran Viet Anh, Vu Sy Hieu Nghia, Lam An Binh | M21: Unbilled | N21: Most hardware-literate entry of the batch (MAX30102, MLX90614, IR retrieval sensor). SAFETY: auto-unlocking emergency medication on a consumer-grade vitals reading should alert a human instead of acting. | O21: 6 members vs cap of 5; Lam An Binh also on B4; no fee record
A22: 21 | B22: Online (database) | C22: 19 | D22: 76 | E22: Bronze | F22: Environment | G22: Indonesia | I22: Republic of Indonesia Defense University | J22: AI SMART TREE | K22: 1 | L22: Ribka Adelina Lubis | M22: Unpaid
A23: 22 | B23: Online (database) | C23: 20 | D23: 76 | E23: Bronze | F23: Environment | G23: Vietnam | I23: Thuong Tin High School | J23: ReGrow AI: Adaptive Swarm System for Autonomous Mangrove Restoration | K23: 1 | L23: To Thi Ngoc Mai | M23: Unpaid
A24: 23 | B24: Online (database) | C24: 21 | D24: 76 | E24: Bronze | F24: Education | G24: Other | H24: Azerbaijan (from school — unconfirmed) | I24: Landau School | J24: MindForge | K24: 1 | L24: Maleyka Jamalova | M24: Unpaid
A25: 24 | B25: BKSTAR | C25: B5 | D25: 75 | E25: Bronze — pending | F25: Environment | G25: Vietnam | I25: BKSTAR Education and Technology JSC | J25: ROV for Aquatic Integrity | K25: 7 | L25: Tran An Phu, Uong Nhat Phong, Duong Tuan Dung, Nguyen Bach Duong, Bui Thai An, Vo Minh Khoi, Pham Chu Minh Quang | M25: Unbilled | N25: Real built hardware (waterproofing, resin cable entries, staged wet tests). VisionConfirm - a module that shows confidence and asks a human before acting - is the best design idea in the batch. The three AI modules are not yet trained. | O25: 7 members vs cap of 5; contradictory registration boxes; no fee record
A26: 25 | B26: Online (database) | C26: 22 | D26: 74 | E26: Bronze | F26: Social Good | G26: Malaysia | I26: SMJK Katholik, Petaling Jaya | J26: Project Guardian Angel | K26: 5 | L26: Regene Ng Kai Xuan, Kong Si Qing, Eng Sze Hui, Lee Shu Peng, Wee Siao See | M26: Paid
A27: 26 | B27: Online (database) | C27: 23 | D27: 73 | E27: Bronze | F27: Social Good | G27: Malaysia | I27: SMJK Katholik | J27: QueueLess Malaysia: AI-Powered Government Services | K27: 5 | L27: Tan Yu Xi, Iong Xin Hui, Lim Ern Xin, Tan Yi Sun, Ng Jia Xin | M27: Paid | N27: Submission text contains an unedited AI artifact.
A28: 27 | B28: Online (database) | C28: 24 | D28: 72 | E28: Bronze | F28: Other | G28: Other | H28: India (from school — unconfirmed) | I28: SVM School, Palladam | J28: AI-Powered Garment Production Planning Assistant | K28: 2 | L28: Gnanaraj Anburaj, Vijayalakshmi | M28: Unpaid | N28: Registered as Teacher / School.
A29: 28 | B29: BKSTAR | C29: B4 | D29: 72 | E29: Bronze — pending | F29: Healthcare | G29: Vietnam | I29: BKSTAR Education and Technology JSC | J29: SoundGuard - AI Smart Glasses That Let Deaf People See Danger and Feel Direction | K29: 7 | L29: Nguyen Viet Trung, Lam An Binh, Trinh Quang Minh, Vo Nguyen Phat, Nguyen Tuan Khanh, Do Ngoc Gia Bao, Nguyen Nhat Minh | M29: Unbilled | N29: Honest about build state - directional alerts, ESP32-S3 integration and offline processing declared unfinished. US$45 BOM. No accuracy, latency or false-alarm figures anywhere; the title sells the unbuilt half. | O29: Two categories ticked (Healthcare + Social Good); 7 members vs cap of 5; Lam An Binh also on B1; no fee record
A30: 29 | B30: Online (database) | C30: 25 | D30: 71 | E30: Bronze | F30: Social Good | G30: Other | H30: India (from school — unconfirmed) | I30: New Vibrant PU College | J30: AI-Enabled Adaptive Communication Resilience System | K30: 1 | L30: Nishanth S | M30: Unpaid | N30: No slides submitted.
A31: 30 | B31: Online (database) | C31: 26 | D31: 71 | E31: Bronze | F31: Healthcare | G31: Other | H31: Egypt (from school/email domain — unconfirmed) | I31: Sharkya STEM School | J31: Dynamic Cardiac Digital Twin for Real-Time AR Surgical Navigation | K31: 2 | L31: Hana Ahmed, Rosol Mohammed | M31: Unpaid | N31: INCOMPLETE: video link 404s, no slides.
A32: 31 | B32: Online (database) | C32: 27 | D32: 70 | E32: Bronze | F32: Education | G32: (not registered) | H32: Vietnam (from email domain — unconfirmed) | I32: Hanoi National University of Education | J32: SAFEDRIVE+: Blood Alcohol Concentration Measurement and Monitoring System | K32: 4 | L32: Nguyen Tri Viet, Nguyen Quang Khe, Nguyen Viet Bach, Nguyen Thuan Quoc Trung | M32: Paid | N32: LATE: ~19h past the 08-30 23:59 PT deadline. Category filed as Education but the project is Transportation/Safety.
A33: 32 | B33: Online (database) | C33: 28 | D33: 70 | E33: Bronze | F33: Social Good | G33: Other | H33: Algeria (from school — unconfirmed) | I33: USTHB, Algiers | J33: Sovereign AI Workforce | K33: 1 | L33: Fateh Abderrahim Boukhalfa | M33: Unpaid
A34: 33 | B34: Online (database) | C34: 29 | D34: 70 | E34: Bronze | F34: Education | G34: Other | H34: India (from school — unconfirmed) | I34: JNCT Professional University, Bhopal | J34: HIJO — AI-Powered Immersive Skill Learning & Assessment | K34: 1 | L34: Aqib Khan | M34: Unpaid | N34: INCOMPLETE: no video, no slides. Video field reads 'https://wedonthavevideodemo'.
A35: 34 | B35: VN Posters | C35: C2 | D35: 70 | E35: Bronze — pending | F35: Finance | G35: Vietnam | I35: Vinschool The Harmony; Foreign Language Specialized School; Vinschool Central Park; Concordia International School Hanoi | J35: AutoInsure AI | K35: 4 | L35: Vu Giang Nam, Vu Ha Bich Diep, Vo Nguyen Minh Thu, Nguyen Minh Dung | M35: Paid (offline) | N35: The only genuine machine learning in the poster batch. Gradient boosting with log-target transform, validation MAE ~1.8M VND / R2 0.96, test MAE 1.76M / R2 0.96, deployed on Streamlit. METHOD: predicts premium (a rate-table output), not risk - the question the team actually asked. | O35: No submission form; no database record
A36: 35 | B36: VN Posters | C36: C3 | D36: 70 | E36: Bronze — pending | F36: Environment | G36: Vietnam | I36: Foreign Trade University; Foreign Language Specialized School; Yen Hoa High School; Le Hong Phong Gifted; Hong Bang High School | J36: Startup with a Project Using Nano-TiO2 Particles to Treat Water Pollution in Van Phuc Silk Village | K36: 6 | L36: Nguyen Linh Chi, Nguyen Bao Khanh, Le Thi Thanh Hang, Nguyen Thuy Duong, Ho Le Gia An, Hoang Dang Phuc | M36: Paid (offline) | N36: Best local specificity in the batch - a named village, a named effluent, an identified product gap, and a cartridge-replacement business model. 92.3% synthesis yield, ~7 nm, 59.1% dye removal in 2h. Filter itself not built. | O36: NO AI COMPONENT; 6 members vs cap of 5; no submission form
A37: 36 | B37: VN Posters | C37: C6 | D37: 70 | E37: Bronze — pending | F37: Environment | G37: Vietnam | I37: HUS Gifted; Newton Grammar School; Le Quy Don Gifted; HNUE Gifted | J37: Development of a Triboelectric Nanogenerator for Self-Powered Portable Electronic Devices | K37: 5 | L37: Pham Xuan Son, Nguyen Minh Duc, Nguyen Vu Manh Khang, Nguyen Nhat Minh, Quan Minh Hong Anh | M37: Paid (offline) | N37: Built a working device for under US$1 and then tested a theory with it - doubling the spacer gap produced the predicted 2.00 voltage ratio, measured on a classroom multimeter. Peak 24.91 V, lit LEDs, ran a floor sensor. No power-into-load or durability data. | O37: NO AI COMPONENT; no submission form
A38: 37 | B38: Online (database) | C38: 30 | D38: 69 | E38: Participation | F38: Education | G38: (not registered) | I38: (not registered) | J38: Ripple.AI | K38: 1 | L38: Maria Kenya Rosari | M38: Unpaid | N38: No registration row — country and school unknown.
A39: 38 | B39: Online (database) | C39: 31 | D39: 63 | E39: Participation | F39: Healthcare | G39: United States | I39: West Career & Technical Academy | J39: DentaLens AI | K39: 1 | L39: Jayden Kim | M39: Unpaid
A40: 39 | B40: VN Posters | C40: C8 | D40: 61 | E40: Participation — pending | F40: Healthcare | G40: Vietnam | I40: Hon Gai High School, Ha Long; UK Academy International Bilingual School, Ha Long | J40: Fabrication of Fe2O3 Magnetic Nanoparticles for Localized Hyperthermia in Cancer Treatment | K40: 2 | L40: Mac Duc Tung, Tran Phuoc Hung | M40: Paid (offline) | N40: Two students, and the only functional test in the nanoparticle group: 45 C in 6 minutes under 55 Oe, inside the therapeutic hyperthermia window. No cell work; heating test conditions underspecified. | O40: NO AI COMPONENT; no submission form
...

Sheet Summary
A1: AI-JAM US 2026 — Verified Award List Summary (44 entries, three batches)
A2: Live COUNTIF against 'Roster Detail'. Award counts use a prefix match so '… — pending' rows are included; all other blocks are exact.
A4: BY AWARD
A5: Award | B5: Teams | C5: Share
A6: Grand Prix (candidate) | B6: =COUNTIF('Roster Detail'!$E$2:$E$45,A6&"*") | C6: =IFERROR(B6/$B$12,0)
A7: Gold | B7: =COUNTIF('Roster Detail'!$E$2:$E$45,A7&"*") | C7: =IFERROR(B7/$B$12,0)
A8: Silver | B8: =COUNTIF('Roster Detail'!$E$2:$E$45,A8&"*") | C8: =IFERROR(B8/$B$12,0)
A9: Bronze | B9: =COUNTIF('Roster Detail'!$E$2:$E$45,A9&"*") | C9: =IFERROR(B9/$B$12,0)
A10: Participation | B10: =COUNTIF('Roster Detail'!$E$2:$E$45,A10&"*") | C10: =IFERROR(B10/$B$12,0)
A11: Non-compliant | B11: =COUNTIF('Roster Detail'!$E$2:$E$45,A11&"*") | C11: =IFERROR(B11/$B$12,0)
A12: Total | B12: =SUM(B6:B11) | C12: =IFERROR(B12/$B$12,0)
A14: BY BATCH
A15: Batch | B15: Teams | C15: Share
A16: Online (database) | B16: =COUNTIF('Roster Detail'!$B$2:$B$45,A16) | C16: =IFERROR(B16/$B$19,0)
A17: BKSTAR | B17: =COUNTIF('Roster Detail'!$B$2:$B$45,A17) | C17: =IFERROR(B17/$B$19,0)
A18: VN Posters | B18: =COUNTIF('Roster Detail'!$B$2:$B$45,A18) | C18: =IFERROR(B18/$B$19,0)
A19: Total | B19: =SUM(B16:B18) | C19: =IFERROR(B19/$B$19,0)
A21: BY CATEGORY
A22: Category | B22: Teams | C22: Share
A23: Agriculture | B23: =COUNTIF('Roster Detail'!$F$2:$F$45,A23) | C23: =IFERROR(B23/$B$31,0)
A24: Education | B24: =COUNTIF('Roster Detail'!$F$2:$F$45,A24) | C24: =IFERROR(B24/$B$31,0)
A25: Environment | B25: =COUNTIF('Roster Detail'!$F$2:$F$45,A25) | C25: =IFERROR(B25/$B$31,0)
A26: Finance | B26: =COUNTIF('Roster Detail'!$F$2:$F$45,A26) | C26: =IFERROR(B26/$B$31,0)
A27: Healthcare | B27: =COUNTIF('Roster Detail'!$F$2:$F$45,A27) | C27: =IFERROR(B27/$B$31,0)
A28: Other | B28: =COUNTIF('Roster Detail'!$F$2:$F$45,A28) | C28: =IFERROR(B28/$B$31,0)
A29: Social Good | B29: =COUNTIF('Roster Detail'!$F$2:$F$45,A29) | C29: =IFERROR(B29/$B$31,0)
A30: Transportation | B30: =COUNTIF('Roster Detail'!$F$2:$F$45,A30) | C30: =IFERROR(B30/$B$31,0)
A31: Total | B31: =SUM(B23:B30) | C31: =IFERROR(B31/$B$31,0)
A33: BY COUNTRY
A34: Country | B34: Teams | C34: Share
A35: (not registered) | B35: =COUNTIF('Roster Detail'!$G$2:$G$45,A35) | C35: =IFERROR(B35/$B$42,0)
A36: Indonesia | B36: =COUNTIF('Roster Detail'!$G$2:$G$45,A36) | C36: =IFERROR(B36/$B$42,0)
A37: Korea | B37: =COUNTIF('Roster Detail'!$G$2:$G$45,A37) | C37: =IFERROR(B37/$B$42,0)
A38: Malaysia | B38: =COUNTIF('Roster Detail'!$G$2:$G$45,A38) | C38: =IFERROR(B38/$B$42,0)
A39: Other | B39: =COUNTIF('Roster Detail'!$G$2:$G$45,A39) | C39: =IFERROR(B39/$B$42,0)
A40: United States | B40: =COUNTIF('Roster Detail'!$G$2:$G$45,A40) | C40: =IFERROR(B40/$B$42,0)
A41: Vietnam | B41: =COUNTIF('Roster Detail'!$G$2:$G$45,A41) | C41: =IFERROR(B41/$B$42,0)
A42: Total | B42: =SUM(B35:B41) | C42: =IFERROR(B42/$B$42,0)
A44: BY ENTRY FEE
A45: Entry Fee | B45: Teams | C45: Share
...

Sheet Open Decisions
A1: # | B1: Applies to | C1: What needs a decision
A2: 1 | B2: Whole list | C2: Award tiers are not final until the paid/unpaid rule is settled. 18 of the 33 online entries did not pay, including the top-scoring one.
A3: 2 | B3: VN Posters — 5 of 6 | C3: NO AI COMPONENT. C3, C4, C5, C6 and C8 are materials-science and physics projects with no model, dataset or algorithm. This is the 11th International AI Invention Challenge. Precedent in the 2026 field: Mimi AI Nanny Robot, scored 59, flagged "No AI component", awarded Participation. If the AI requirement is enforced, only C2 (AutoInsure AI) survives as a Bronze from that batch.
A4: 3 | B4: BKSTAR — all 5 | C4: No entry-fee record exists for info@bkstar.edu.vn. At $350 standard / $250 student that is $1,750 or $1,250 unbilled across five entries.
A5: 4 | B5: BKSTAR — all 5 | C5: One award recipient (Pham Van Khuong, Hanoi) is named on all five forms. Certificates and awards for 33 students would ship to a single teacher address. Confirm this is intended.
A6: 5 | B6: BKSTAR + rank 13 | C6: Team sizes over the stated cap of 5: B1 and B2 have 6, B3, B4 and B5 have 7, C3 and C5 have 6. Rank 13 (Hydroclimate) already carried the same issue with 7 authors.
A7: 6 | B7: B3 | C7: Required 30-second video is blank and no slides were submitted. Incomplete on the face of the form.
A8: 7 | B8: VN Posters — all | C8: No submission forms were provided — only names, schools, titles and links. Abstract, key features, social impact and marketability were never submitted. Scores come from the posters instead.
A9: 8 | B9: VN Posters | C9: Group 7 is missing from the numbering (1, 2, 3, 4, 5, 6, 8). Confirm whether a group was lost.
A10: 9 | B10: VN Posters — Group 1 | C10: Group 1 is SafeDrive+, already in the database and already scored as rank 27 / 70 / Bronze with a late-submission flag. It is NOT duplicated in this workbook. Do not award it twice.
A11: 10 | B11: Name collisions | C11: Lam An Binh appears on both B1 and B4 — same person, two teams. Nguyen Thuy Duong appears on C3 and C5, and Nguyen Nhat Minh on B4 and C6 — different schools, so probably different students with the same name. Confirm all three before printing certificates.
A12: 11 | B12: Rank 13 | C12: Hydroclimate: 7 authors against the 5-member cap and the co-authors read as university faculty. Eligibility call needed.
A13: 12 | B13: Rank 15 | C13: NeoGuardian AI: no registration row and two submissions from the same address — check for a duplicate charge.
... A18: 17 | B18: Minor participants | C18: Several entrants are secondary-school students. The agreed publication rule is: top awards on the web, full roster in a PDF only.

Sheet About This File
A1: AI-JAM US 2026 — Verified Award List
A3: Every name, project title, country, school and score in this workbook came from a real submission —
A4: the competition database, five emailed DOCX forms, or seven Google Drive posters that were read in full.
A5: Nothing here is invented.
A7: Three batches, 44 entries
A8: Online (database) — 33 entries. 39 submission rows minus 2 test records and 4 duplicates. 15 paid, 18 unpaid.
A9: BKSTAR — 5 entries. Emailed forms from one Vietnamese institution, one submitting account, 33 students.
A10: No database record and no fee record.
A11: VN Posters — 6 entries. Seven groups submitted; Group 1 is SafeDrive+, already scored in the online batch,
A12: so it is not repeated here. No database record; fees stated as paid offline.
A14: Format
A15: Sheet 1 uses the six columns of the 2025 AI-JAM US Awardee List: No. / Category / Country /
... A31: draft, not a roster. It must not be published, sent to a participant, or merged with this file.
